<?xml version="1.0"?>

<robot name="rrr_bot" xmlns:xacro="http://www.ros.org/wiki/xacro">
    <!-- INCLUDE XACRO-->
    <xacro:include filename="$(find first_rrr)/urdf/names.xacro"/>
    <xacro:include filename="$(find first_rrr)/urdf/material.xacro"/>
    <xacro:include filename="$(find first_rrr)/urdf/robot_rrr.gazebo"/> 
    <!-- Virtual link of world SDR-->
    <link name="world"/>

    <link name="${b_l}">
        <visual>
            <origin xyz="0 0 0.1" rpy="0 0 0"/>
            <geometry>
                <cylinder radius="0.3" length="0.2"/>
            </geometry>
            <material name="orange"/>
        </visual>
        <collision> 
            <origin xyz="0 0 0.1" rpy="0 0 0"/>
            <geometry>
                <cylinder radius="0.3" length="0.2"/>
            </geometry>
        </collision>
        <inertial>
            <origin xyz="0 0 0.1" rpy="0 0 0"/>
            <mass value="${mass_l1}"/>
            <inertia
            ixx="${inertial}" ixy="0.0" ixz="0.0"
            iyy="${inertial}" iyz="0.0"
            izz="${inertial}"/>
        </inertial>
    </link>

    <joint name="world_robot_fix_jnt" type="fixed">
        <parent link="world"/>
        <child link="${b_l}"/>
    </joint>

    <link name="${l1}">
        <visual>
            <origin xyz="0 0 0" rpy="0 0 0"/>
            <geometry>
            <mesh filename="package://first_rrr/urdf/STL/base.stl" scale="0.1 0.1 0.1"/>
            </geometry>
            <material name="white"/>
        </visual>
        <collision>
            <origin xyz="0 0 0" rpy="0 0 0"/>
            <geometry>
                <cylinder radius="0.3" length="0.319"/>
            </geometry>
        </collision>
        <inertial>
            <origin xyz="0 0 0.1" rpy="0 0 0"/>
            <mass value="${mass_l1}"/>
            <inertia
            ixx="${inertial}" ixy="0.0" ixz="0.0"
            iyy="${inertial}" iyz="0.0"
            izz="${inertial}"/>
        </inertial>
    </link>

    <joint name="${j1}" type="continuous">
        <parent link="${b_l}"/>
        <child link="${l1}"/>
        <origin xyz="0 0 0.2"/>
        <axis xyz="0 0 1"/>
    </joint>

    <link name="${l2}">
        <visual>
            <origin xyz="0 -0.005 -0.065" rpy="0 0 0"/>
            <geometry>
            <mesh filename="package://first_rrr/urdf/STL/birinci_kol.stl" scale="0.1 0.1 0.1"/>
            
            </geometry> 
            <material name="white"/>
        </visual>
        <inertial>
            <origin xyz="0 0 0.1" rpy="0 0 0"/>
            <mass value="${mass_l1}"/>
            <inertia
            ixx="${inertial}" ixy="0.0" ixz="0.0"
            iyy="${inertial}" iyz="0.0"
            izz="${inertial}"/>
        </inertial>
        <collision>
             <origin xyz="0 0 0.5" rpy="0 0 0"/>
            <geometry>
                <cylinder radius="0.1" length="1.3"/>
            </geometry> 
        </collision>
    </link>
     <joint name="${j2}" type="continuous">
        <parent link="${l1}"/>
        <child link="${l2}"/>
        <origin xyz="0 0.0005 0.519" rpy="${PI/6} 0 0"/>
        <axis xyz="1 0 0"/>
        
    </joint>
<link name="${l3}">
    <visual>
        <origin xyz="0 -0.005 -0.065" rpy="0 0 0"/>
        <geometry>
        <mesh filename="package://first_rrr/urdf/STL/birinci_kol.stl" scale="0.1 0.1 0.1"/>
        
        </geometry> 
        <material name="white"/>
    </visual>
    <inertial>
        <origin xyz="0 0 0.1" rpy="0 0 0"/>
        <mass value="${mass_l1}"/>
        <inertia
        ixx="${inertial}" ixy="0.0" ixz="0.0"
        iyy="${inertial}" iyz="0.0"
        izz="${inertial}"/>
    </inertial>
    <collision>
            <origin xyz="0 0 0.5" rpy="0 0 0"/>
        <geometry>
            <cylinder radius="0.1" length="1.3"/>
        </geometry> 
    </collision>
</link>
    <joint name="${j3}" type="continuous">
    <parent link="${l2}"/>
    <child link="${l3}"/>
    <origin xyz="0 0.53 0.95" rpy="0 0 0"/>
    <axis xyz="1 0 0"/>
    
</joint>
<link name="${l4}">
    <visual>
        <origin xyz="0 0 0" rpy="0 0 0"/>
        <geometry>
            <box size="0.1 0.1 0.1"/>

        
        </geometry> 
        <material name="orange"/>
    </visual>
    <inertial>
        <origin xyz="0 0 0.1" rpy="0 0 0"/>
        <mass value="${mass_l1}"/>
        <inertia
        ixx="${inertial}" ixy="0.0" ixz="0.0"
        iyy="${inertial}" iyz="0.0"
        izz="${inertial}"/>
    </inertial>
    <collision>
            <origin xyz="0 0 0" rpy="0 0 0"/>
        <geometry>
            <box size="0.1 0.1 0.1"/>
        </geometry> 
    </collision>
</link>
    <joint name="ee_joint" type="fixed">
    <parent link="${l3}"/>
    <child link="${l4}"/>
    <origin xyz="0 0.53 0.95" rpy="0 0 0"/>
    
    
</joint>
    <transmission name="tran1">
        <type>transmission_interface/SimpleTransmission</type>
        <joint name="${j1}">
            <hardwareInterface>hardware_interface/EffortJointInterface</hardwareInterface>
        </joint>
        <actuator name="motor1">
            <hardwareInterface>hardware_interface/EffortJointInterface</hardwareInterface>
            <mechanicalReduction>1</mechanicalReduction>
        </actuator>
    </transmission>

    <transmission name="tran2">
        <type>transmission_interface/SimpleTransmission</type>
        <joint name="${j2}">
        <hardwareInterface>hardware_interface/EffortJointInterface</hardwareInterface>
        </joint>
        <actuator name="motor2">
            <hardwareInterface>hardware_interface/EffortJointInterface</hardwareInterface>
            <mechanicalReduction>1</mechanicalReduction>
        </actuator>
    </transmission>


    <transmission name="tran3">
        <type>transmission_interface/SimpleTransmission</type>
        <joint name="${j3}">
        <hardwareInterface>hardware_interface/EffortJointInterface</hardwareInterface>
        </joint>
        <actuator name="motor3">
            <hardwareInterface>hardware_interface/EffortJointInterface</hardwareInterface>
            <mechanicalReduction>1</mechanicalReduction>
        </actuator>
    </transmission>
</robot>